<?xml version="1.0" encoding="UTF-8"?>
<testng-results skipped="1" failed="1" ignored="1" total="5" passed="2">
  <reporter-output>
  </reporter-output>
  <suite name="Default suite" duration-ms="102" started-at="2023-02-12T23:51:30 IST" finished-at="2023-02-12T23:51:30 IST">
    <groups>
    </groups>
    <test name="Default test" duration-ms="102" started-at="2023-02-12T23:51:30 IST" finished-at="2023-02-12T23:51:30 IST">
      <class name="three.Practice_Automation">
        <test-method status="PASS" signature="m3()[pri:0, instance:three.Practice_Automation@7b69c6ba]" name="m3" duration-ms="8" started-at="2023-02-12T23:51:30 IST" finished-at="2023-02-12T23:51:30 IST">
          <reporter-output>
          </reporter-output>
        </test-method> <!-- m3 -->
        <test-method status="PASS" signature="m5()[pri:0, instance:three.Practice_Automation@7b69c6ba]" name="m5" duration-ms="2" started-at="2023-02-12T23:51:30 IST" finished-at="2023-02-12T23:51:30 IST">
          <reporter-output>
          </reporter-output>
        </test-method> <!-- m5 -->
        <test-method status="FAIL" signature="m2()[pri:2, instance:three.Practice_Automation@7b69c6ba]" name="m2" duration-ms="6" started-at="2023-02-12T23:51:30 IST" finished-at="2023-02-12T23:51:30 IST">
          <exception class="java.lang.AssertionError">
            <message>
              <![CDATA[expected [false] but found [true]]]>
            </message>
            <full-stacktrace>
              <![CDATA[java.lang.AssertionError: expected [false] but found [true]
at org.testng.Assert.fail(Assert.java:99)
at org.testng.Assert.failNotEquals(Assert.java:1037)
at org.testng.Assert.assertEqualsImpl(Assert.java:140)
at org.testng.Assert.assertEquals(Assert.java:122)
at org.testng.Assert.assertEquals(Assert.java:819)
at org.testng.Assert.assertEquals(Assert.java:829)
at three.Practice_Automation.m2(Practice_Automation.java:21)
at sun.reflect.NativeMethodAccessorImpl.invoke0(Native Method)
at sun.reflect.NativeMethodAccessorImpl.invoke(Unknown Source)
at sun.reflect.DelegatingMethodAccessorImpl.invoke(Unknown Source)
at java.lang.reflect.Method.invoke(Unknown Source)
at org.testng.internal.MethodInvocationHelper.invokeMethod(MethodInvocationHelper.java:132)
at org.testng.internal.TestInvoker.invokeMethod(TestInvoker.java:599)
at org.testng.internal.TestInvoker.invokeTestMethod(TestInvoker.java:174)
at org.testng.internal.MethodRunner.runInSequence(MethodRunner.java:46)
at org.testng.internal.TestInvoker$MethodInvocationAgent.invoke(TestInvoker.java:822)
at org.testng.internal.TestInvoker.invokeTestMethods(TestInvoker.java:147)
at org.testng.internal.TestMethodWorker.invokeTestMethods(TestMethodWorker.java:146)
at org.testng.internal.TestMethodWorker.run(TestMethodWorker.java:128)
at java.util.ArrayList.forEach(Unknown Source)
at org.testng.TestRunner.privateRun(TestRunner.java:764)
at org.testng.TestRunner.run(TestRunner.java:585)
at org.testng.SuiteRunner.runTest(SuiteRunner.java:384)
at org.testng.SuiteRunner.runSequentially(SuiteRunner.java:378)
at org.testng.SuiteRunner.privateRun(SuiteRunner.java:337)
at org.testng.SuiteRunner.run(SuiteRunner.java:286)
at org.testng.SuiteRunnerWorker.runSuite(SuiteRunnerWorker.java:53)
at org.testng.SuiteRunnerWorker.run(SuiteRunnerWorker.java:96)
at org.testng.TestNG.runSuitesSequentially(TestNG.java:1218)
at org.testng.TestNG.runSuitesLocally(TestNG.java:1140)
at org.testng.TestNG.runSuites(TestNG.java:1069)
at org.testng.TestNG.run(TestNG.java:1037)
at org.testng.remote.AbstractRemoteTestNG.run(AbstractRemoteTestNG.java:115)
at org.testng.remote.RemoteTestNG.initAndRun(RemoteTestNG.java:251)
at org.testng.remote.RemoteTestNG.main(RemoteTestNG.java:77)
]]>
            </full-stacktrace>
          </exception> <!-- java.lang.AssertionError -->
          <reporter-output>
          </reporter-output>
        </test-method> <!-- m2 -->
        <test-method status="SKIP" signature="m4()[pri:0, instance:three.Practice_Automation@7b69c6ba]" name="m4" duration-ms="0" started-at="2023-02-12T23:51:30 IST" depends-on-methods="three.Practice_Automation.m2" finished-at="2023-02-12T23:51:30 IST">
          <exception class="java.lang.Throwable">
            <message>
              <![CDATA[Method Practice_Automation.m4()[pri:0, instance:three.Practice_Automation@7b69c6ba] depends on not successfully finished methods]]>
            </message>
            <full-stacktrace>
              <![CDATA[java.lang.Throwable: Method Practice_Automation.m4()[pri:0, instance:three.Practice_Automation@7b69c6ba] depends on not successfully finished methods
at org.testng.internal.TestInvoker.invokeTestMethods(TestInvoker.java:102)
at org.testng.internal.TestMethodWorker.invokeTestMethods(TestMethodWorker.java:146)
at org.testng.internal.TestMethodWorker.run(TestMethodWorker.java:128)
at java.util.ArrayList.forEach(Unknown Source)
at org.testng.TestRunner.privateRun(TestRunner.java:764)
at org.testng.TestRunner.run(TestRunner.java:585)
at org.testng.SuiteRunner.runTest(SuiteRunner.java:384)
at org.testng.SuiteRunner.runSequentially(SuiteRunner.java:378)
at org.testng.SuiteRunner.privateRun(SuiteRunner.java:337)
at org.testng.SuiteRunner.run(SuiteRunner.java:286)
at org.testng.SuiteRunnerWorker.runSuite(SuiteRunnerWorker.java:53)
at org.testng.SuiteRunnerWorker.run(SuiteRunnerWorker.java:96)
at org.testng.TestNG.runSuitesSequentially(TestNG.java:1218)
at org.testng.TestNG.runSuitesLocally(TestNG.java:1140)
at org.testng.TestNG.runSuites(TestNG.java:1069)
at org.testng.TestNG.run(TestNG.java:1037)
at org.testng.remote.AbstractRemoteTestNG.run(AbstractRemoteTestNG.java:115)
at org.testng.remote.RemoteTestNG.initAndRun(RemoteTestNG.java:251)
at org.testng.remote.RemoteTestNG.main(RemoteTestNG.java:77)
]]>
            </full-stacktrace>
          </exception> <!-- java.lang.Throwable -->
          <reporter-output>
          </reporter-output>
        </test-method> <!-- m4 -->
      </class> <!-- three.Practice_Automation -->
    </test> <!-- Default test -->
  </suite> <!-- Default suite -->
</testng-results>
